2018-06-18 14:50:18,156 INFO: Yewz Startup [in C:\Users\cmarsh\YewzOfficial\app\__init__.py:38]
2018-06-18 14:50:23,933 INFO: Yewz Startup [in C:\Users\cmarsh\YewzOfficial\app\__init__.py:38]
2018-06-18 15:02:40,803 ERROR: Exception on /subscribe [POST] [in c:\users\cmarsh\appdata\local\programs\python\python36-32\lib\site-packages\flask\app.py:1761]
Traceback (most recent call last):
  File "c:\users\cmarsh\appdata\local\programs\python\python36-32\lib\site-packages\sqlalchemy\engine\base.py", line 1193, in _execute_context
    context)
  File "c:\users\cmarsh\appdata\local\programs\python\python36-32\lib\site-packages\sqlalchemy\engine\default.py", line 508, in do_execute
    cursor.execute(statement, parameters)
  File "c:\users\cmarsh\appdata\local\programs\python\python36-32\lib\site-packages\MySQLdb\cursors.py", line 250, in execute
    self.errorhandler(self, exc, value)
  File "c:\users\cmarsh\appdata\local\programs\python\python36-32\lib\site-packages\MySQLdb\connections.py", line 50, in defaulterrorhandler
    raise errorvalue
  File "c:\users\cmarsh\appdata\local\programs\python\python36-32\lib\site-packages\MySQLdb\cursors.py", line 247, in execute
    res = self._query(query)
  File "c:\users\cmarsh\appdata\local\programs\python\python36-32\lib\site-packages\MySQLdb\cursors.py", line 411, in _query
    rowcount = self._do_query(q)
  File "c:\users\cmarsh\appdata\local\programs\python\python36-32\lib\site-packages\MySQLdb\cursors.py", line 374, in _do_query
    db.query(q)
  File "c:\users\cmarsh\appdata\local\programs\python\python36-32\lib\site-packages\MySQLdb\connections.py", line 277, in query
    _mysql.connection.query(self, query)
_mysql_exceptions.IntegrityError: (1062, "Duplicate entry 'test@test.com' for key 'PRIMARY'")

The above exception was the direct cause of the following exception:

Traceback (most recent call last):
  File "c:\users\cmarsh\appdata\local\programs\python\python36-32\lib\site-packages\flask\app.py", line 2292, in wsgi_app
    response = self.full_dispatch_request()
  File "c:\users\cmarsh\appdata\local\programs\python\python36-32\lib\site-packages\flask\app.py", line 1815, in full_dispatch_request
    rv = self.handle_user_exception(e)
  File "c:\users\cmarsh\appdata\local\programs\python\python36-32\lib\site-packages\flask\app.py", line 1718, in handle_user_exception
    reraise(exc_type, exc_value, tb)
  File "c:\users\cmarsh\appdata\local\programs\python\python36-32\lib\site-packages\flask\_compat.py", line 35, in reraise
    raise value
  File "c:\users\cmarsh\appdata\local\programs\python\python36-32\lib\site-packages\flask\app.py", line 1813, in full_dispatch_request
    rv = self.dispatch_request()
  File "c:\users\cmarsh\appdata\local\programs\python\python36-32\lib\site-packages\flask\app.py", line 1799, in dispatch_request
    return self.view_functions[rule.endpoint](**req.view_args)
  File "C:\Users\cmarsh\YewzOfficial\app\routes.py", line 24, in subscribe
    db.session.commit()
  File "c:\users\cmarsh\appdata\local\programs\python\python36-32\lib\site-packages\sqlalchemy\orm\scoping.py", line 153, in do
    return getattr(self.registry(), name)(*args, **kwargs)
  File "c:\users\cmarsh\appdata\local\programs\python\python36-32\lib\site-packages\sqlalchemy\orm\session.py", line 943, in commit
    self.transaction.commit()
  File "c:\users\cmarsh\appdata\local\programs\python\python36-32\lib\site-packages\sqlalchemy\orm\session.py", line 467, in commit
    self._prepare_impl()
  File "c:\users\cmarsh\appdata\local\programs\python\python36-32\lib\site-packages\sqlalchemy\orm\session.py", line 447, in _prepare_impl
    self.session.flush()
  File "c:\users\cmarsh\appdata\local\programs\python\python36-32\lib\site-packages\sqlalchemy\orm\session.py", line 2254, in flush
    self._flush(objects)
  File "c:\users\cmarsh\appdata\local\programs\python\python36-32\lib\site-packages\sqlalchemy\orm\session.py", line 2380, in _flush
    transaction.rollback(_capture_exception=True)
  File "c:\users\cmarsh\appdata\local\programs\python\python36-32\lib\site-packages\sqlalchemy\util\langhelpers.py", line 66, in __exit__
    compat.reraise(exc_type, exc_value, exc_tb)
  File "c:\users\cmarsh\appdata\local\programs\python\python36-32\lib\site-packages\sqlalchemy\util\compat.py", line 187, in reraise
    raise value
  File "c:\users\cmarsh\appdata\local\programs\python\python36-32\lib\site-packages\sqlalchemy\orm\session.py", line 2344, in _flush
    flush_context.execute()
  File "c:\users\cmarsh\appdata\local\programs\python\python36-32\lib\site-packages\sqlalchemy\orm\unitofwork.py", line 391, in execute
    rec.execute(self)
  File "c:\users\cmarsh\appdata\local\programs\python\python36-32\lib\site-packages\sqlalchemy\orm\unitofwork.py", line 556, in execute
    uow
  File "c:\users\cmarsh\appdata\local\programs\python\python36-32\lib\site-packages\sqlalchemy\orm\persistence.py", line 181, in save_obj
    mapper, table, insert)
  File "c:\users\cmarsh\appdata\local\programs\python\python36-32\lib\site-packages\sqlalchemy\orm\persistence.py", line 830, in _emit_insert_statements
    execute(statement, multiparams)
  File "c:\users\cmarsh\appdata\local\programs\python\python36-32\lib\site-packages\sqlalchemy\engine\base.py", line 948, in execute
    return meth(self, multiparams, params)
  File "c:\users\cmarsh\appdata\local\programs\python\python36-32\lib\site-packages\sqlalchemy\sql\elements.py", line 269, in _execute_on_connection
    return connection._execute_clauseelement(self, multiparams, params)
  File "c:\users\cmarsh\appdata\local\programs\python\python36-32\lib\site-packages\sqlalchemy\engine\base.py", line 1060, in _execute_clauseelement
    compiled_sql, distilled_params
  File "c:\users\cmarsh\appdata\local\programs\python\python36-32\lib\site-packages\sqlalchemy\engine\base.py", line 1200, in _execute_context
    context)
  File "c:\users\cmarsh\appdata\local\programs\python\python36-32\lib\site-packages\sqlalchemy\engine\base.py", line 1413, in _handle_dbapi_exception
    exc_info
  File "c:\users\cmarsh\appdata\local\programs\python\python36-32\lib\site-packages\sqlalchemy\util\compat.py", line 203, in raise_from_cause
    reraise(type(exception), exception, tb=exc_tb, cause=cause)
  File "c:\users\cmarsh\appdata\local\programs\python\python36-32\lib\site-packages\sqlalchemy\util\compat.py", line 186, in reraise
    raise value.with_traceback(tb)
  File "c:\users\cmarsh\appdata\local\programs\python\python36-32\lib\site-packages\sqlalchemy\engine\base.py", line 1193, in _execute_context
    context)
  File "c:\users\cmarsh\appdata\local\programs\python\python36-32\lib\site-packages\sqlalchemy\engine\default.py", line 508, in do_execute
    cursor.execute(statement, parameters)
  File "c:\users\cmarsh\appdata\local\programs\python\python36-32\lib\site-packages\MySQLdb\cursors.py", line 250, in execute
    self.errorhandler(self, exc, value)
  File "c:\users\cmarsh\appdata\local\programs\python\python36-32\lib\site-packages\MySQLdb\connections.py", line 50, in defaulterrorhandler
    raise errorvalue
  File "c:\users\cmarsh\appdata\local\programs\python\python36-32\lib\site-packages\MySQLdb\cursors.py", line 247, in execute
    res = self._query(query)
  File "c:\users\cmarsh\appdata\local\programs\python\python36-32\lib\site-packages\MySQLdb\cursors.py", line 411, in _query
    rowcount = self._do_query(q)
  File "c:\users\cmarsh\appdata\local\programs\python\python36-32\lib\site-packages\MySQLdb\cursors.py", line 374, in _do_query
    db.query(q)
  File "c:\users\cmarsh\appdata\local\programs\python\python36-32\lib\site-packages\MySQLdb\connections.py", line 277, in query
    _mysql.connection.query(self, query)
sqlalchemy.exc.IntegrityError: (_mysql_exceptions.IntegrityError) (1062, "Duplicate entry 'test@test.com' for key 'PRIMARY'") [SQL: 'INSERT INTO user_email (email_addr) VALUES (%s)'] [parameters: ('test@test.com',)] (Background on this error at: http://sqlalche.me/e/gkpj)
